[2024-09-24T11:13:11.894+0000] {local_task_job_runner.py:123} INFO - ::group::Pre task execution logs
[2024-09-24T11:13:11.932+0000] {taskinstance.py:2612} INFO - Dependencies all met for dep_context=non-requeueable deps ti=<TaskInstance: dbt_dag.dbt_seed manual__2024-09-24T11:13:11.218127+00:00 [queued]>
[2024-09-24T11:13:11.949+0000] {taskinstance.py:2612} INFO - Dependencies all met for dep_context=requeueable deps ti=<TaskInstance: dbt_dag.dbt_seed manual__2024-09-24T11:13:11.218127+00:00 [queued]>
[2024-09-24T11:13:11.950+0000] {taskinstance.py:2865} INFO - Starting attempt 1 of 1
[2024-09-24T11:13:11.981+0000] {taskinstance.py:2888} INFO - Executing <Task(BashOperator): dbt_seed> on 2024-09-24 11:13:11.218127+00:00
[2024-09-24T11:13:11.993+0000] {logging_mixin.py:190} WARNING - /home/***/.local/lib/python3.12/site-packages/***/task/task_runner/standard_task_runner.py:70 DeprecationWarning: This process (pid=498) is multi-threaded, use of fork() may lead to deadlocks in the child.
[2024-09-24T11:13:11.994+0000] {standard_task_runner.py:72} INFO - Started process 499 to run task
[2024-09-24T11:13:11.993+0000] {standard_task_runner.py:104} INFO - Running: ['***', 'tasks', 'run', 'dbt_dag', 'dbt_seed', 'manual__2024-09-24T11:13:11.218127+00:00', '--job-id', '36', '--raw', '--subdir', 'DAGS_FOLDER/dbt_snowflake_dag.py', '--cfg-path', '/tmp/tmp2dflmavs']
[2024-09-24T11:13:11.997+0000] {standard_task_runner.py:105} INFO - Job 36: Subtask dbt_seed
[2024-09-24T11:13:12.019+0000] {logging_mixin.py:190} WARNING - /home/***/.local/lib/python3.12/site-packages/***/settings.py:209 DeprecationWarning: The sql_alchemy_conn option in [core] has been moved to the sql_alchemy_conn option in [database] - the old setting has been used, but please update your config.
[2024-09-24T11:13:12.080+0000] {task_command.py:467} INFO - Running <TaskInstance: dbt_dag.dbt_seed manual__2024-09-24T11:13:11.218127+00:00 [running]> on host cb04601716d3
[2024-09-24T11:13:12.293+0000] {taskinstance.py:3131} INFO - Exporting env vars: AIRFLOW_CTX_DAG_OWNER='Amir' AIRFLOW_CTX_DAG_ID='dbt_dag' AIRFLOW_CTX_TASK_ID='dbt_seed' AIRFLOW_CTX_EXECUTION_DATE='2024-09-24T11:13:11.218127+00:00' AIRFLOW_CTX_TRY_NUMBER='1' AIRFLOW_CTX_DAG_RUN_ID='manual__2024-09-24T11:13:11.218127+00:00'
[2024-09-24T11:13:12.295+0000] {taskinstance.py:731} INFO - ::endgroup::
[2024-09-24T11:13:12.441+0000] {subprocess.py:63} INFO - Tmp dir root location: /tmp
[2024-09-24T11:13:12.443+0000] {subprocess.py:75} INFO - Running command: ['/usr/bin/bash', '-c', 'dbt seed']
[2024-09-24T11:13:12.479+0000] {subprocess.py:86} INFO - Output:
[2024-09-24T11:13:17.227+0000] {subprocess.py:93} INFO - Usage: dbt seed [OPTIONS]
[2024-09-24T11:13:17.228+0000] {subprocess.py:93} INFO - Try 'dbt seed -h' for help.
[2024-09-24T11:13:17.228+0000] {subprocess.py:93} INFO - 
[2024-09-24T11:13:17.229+0000] {subprocess.py:93} INFO - Error: Invalid value for '--profiles-dir': Path '/home/***/.dbt' does not exist.
[2024-09-24T11:13:17.618+0000] {subprocess.py:97} INFO - Command exited with return code 2
[2024-09-24T11:13:17.636+0000] {taskinstance.py:3310} ERROR - Task failed with exception
Traceback (most recent call last):
  File "/home/airflow/.local/lib/python3.12/site-packages/airflow/models/taskinstance.py", line 767, in _execute_task
    result = _execute_callable(context=context, **execute_callable_kwargs)
             ^^^^^^^^^^^^^^^^^^^^^^^^^^^^^^^^^^^^^^^^^^^^^^^^^^^^^^^^^^^^^
  File "/home/airflow/.local/lib/python3.12/site-packages/airflow/models/taskinstance.py", line 733, in _execute_callable
    return ExecutionCallableRunner(
           ^^^^^^^^^^^^^^^^^^^^^^^^
  File "/home/airflow/.local/lib/python3.12/site-packages/airflow/utils/operator_helpers.py", line 252, in run
    return self.func(*args, **kwargs)
           ^^^^^^^^^^^^^^^^^^^^^^^^^^
  File "/home/airflow/.local/lib/python3.12/site-packages/airflow/models/baseoperator.py", line 406, in wrapper
    return func(self, *args, **kwargs)
           ^^^^^^^^^^^^^^^^^^^^^^^^^^^
  File "/home/airflow/.local/lib/python3.12/site-packages/airflow/operators/bash.py", line 249, in execute
    raise AirflowException(
airflow.exceptions.AirflowException: Bash command failed. The command returned a non-zero exit code 2.
[2024-09-24T11:13:17.644+0000] {taskinstance.py:1225} INFO - Marking task as FAILED. dag_id=dbt_dag, task_id=dbt_seed, run_id=manual__2024-09-24T11:13:11.218127+00:00, execution_date=20240924T111311, start_date=20240924T111311, end_date=20240924T111317
[2024-09-24T11:13:17.674+0000] {taskinstance.py:340} INFO - ::group::Post task execution logs
[2024-09-24T11:13:17.676+0000] {standard_task_runner.py:124} ERROR - Failed to execute job 36 for task dbt_seed (Bash command failed. The command returned a non-zero exit code 2.; 499)
Traceback (most recent call last):
  File "/home/airflow/.local/lib/python3.12/site-packages/airflow/task/task_runner/standard_task_runner.py", line 117, in _start_by_fork
    ret = args.func(args, dag=self.dag)
          ^^^^^^^^^^^^^^^^^^^^^^^^^^^^^
  File "/home/airflow/.local/lib/python3.12/site-packages/airflow/cli/cli_config.py", line 49, in command
    return func(*args, **kwargs)
           ^^^^^^^^^^^^^^^^^^^^^
  File "/home/airflow/.local/lib/python3.12/site-packages/airflow/utils/cli.py", line 115, in wrapper
    return f(*args, **kwargs)
           ^^^^^^^^^^^^^^^^^^
  File "/home/airflow/.local/lib/python3.12/site-packages/airflow/cli/commands/task_command.py", line 483, in task_run
    task_return_code = _run_task_by_selected_method(args, _dag, ti)
                       ^^^^^^^^^^^^^^^^^^^^^^^^^^^^^^^^^^^^^^^^^^^^
  File "/home/airflow/.local/lib/python3.12/site-packages/airflow/cli/commands/task_command.py", line 256, in _run_task_by_selected_method
    return _run_raw_task(args, ti)
           ^^^^^^^^^^^^^^^^^^^^^^^
  File "/home/airflow/.local/lib/python3.12/site-packages/airflow/cli/commands/task_command.py", line 341, in _run_raw_task
    return ti._run_raw_task(
           ^^^^^^^^^^^^^^^^^
  File "/home/airflow/.local/lib/python3.12/site-packages/airflow/utils/session.py", line 97, in wrapper
    return func(*args, session=session, **kwargs)
           ^^^^^^^^^^^^^^^^^^^^^^^^^^^^^^^^^^^^^^
  File "/home/airflow/.local/lib/python3.12/site-packages/airflow/models/taskinstance.py", line 3004, in _run_raw_task
    return _run_raw_task(
           ^^^^^^^^^^^^^^
  File "/home/airflow/.local/lib/python3.12/site-packages/airflow/models/taskinstance.py", line 273, in _run_raw_task
    TaskInstance._execute_task_with_callbacks(
  File "/home/airflow/.local/lib/python3.12/site-packages/airflow/models/taskinstance.py", line 3158, in _execute_task_with_callbacks
    result = self._execute_task(context, task_orig)
             ^^^^^^^^^^^^^^^^^^^^^^^^^^^^^^^^^^^^^^
  File "/home/airflow/.local/lib/python3.12/site-packages/airflow/models/taskinstance.py", line 3182, in _execute_task
    return _execute_task(self, context, task_orig)
           ^^^^^^^^^^^^^^^^^^^^^^^^^^^^^^^^^^^^^^^
  File "/home/airflow/.local/lib/python3.12/site-packages/airflow/models/taskinstance.py", line 767, in _execute_task
    result = _execute_callable(context=context, **execute_callable_kwargs)
             ^^^^^^^^^^^^^^^^^^^^^^^^^^^^^^^^^^^^^^^^^^^^^^^^^^^^^^^^^^^^^
  File "/home/airflow/.local/lib/python3.12/site-packages/airflow/models/taskinstance.py", line 733, in _execute_callable
    return ExecutionCallableRunner(
           ^^^^^^^^^^^^^^^^^^^^^^^^
  File "/home/airflow/.local/lib/python3.12/site-packages/airflow/utils/operator_helpers.py", line 252, in run
    return self.func(*args, **kwargs)
           ^^^^^^^^^^^^^^^^^^^^^^^^^^
  File "/home/airflow/.local/lib/python3.12/site-packages/airflow/models/baseoperator.py", line 406, in wrapper
    return func(self, *args, **kwargs)
           ^^^^^^^^^^^^^^^^^^^^^^^^^^^
  File "/home/airflow/.local/lib/python3.12/site-packages/airflow/operators/bash.py", line 249, in execute
    raise AirflowException(
airflow.exceptions.AirflowException: Bash command failed. The command returned a non-zero exit code 2.
[2024-09-24T11:13:17.720+0000] {local_task_job_runner.py:266} INFO - Task exited with return code 1
[2024-09-24T11:13:17.751+0000] {taskinstance.py:3900} INFO - 0 downstream tasks scheduled from follow-on schedule check
[2024-09-24T11:13:17.754+0000] {local_task_job_runner.py:245} INFO - ::endgroup::
